Performing system checks...

System check identified no issues (0 silenced).
February 12, 2022 - 18:41:56
Django version 3.0.7, using settings 'backend.settings'
Starting development server at http://0.0.0.0:8000/
Quit the server with CONTROL-C.
Traceback (most recent call last):
  File "manage.py", line 22, in <module>
    main()
  File "manage.py", line 18, in main
    execute_from_command_line(sys.argv)
  File "/home/abhiram/anaconda3/lib/python3.7/site-packages/django/core/management/__init__.py", line 401, in execute_from_command_line
    utility.execute()
  File "/home/abhiram/anaconda3/lib/python3.7/site-packages/django/core/management/__init__.py", line 345, in execute
    settings.INSTALLED_APPS
  File "/home/abhiram/anaconda3/lib/python3.7/site-packages/django/conf/__init__.py", line 76, in __getattr__
    self._setup(name)
  File "/home/abhiram/anaconda3/lib/python3.7/site-packages/django/conf/__init__.py", line 63, in _setup
    self._wrapped = Settings(settings_module)
  File "/home/abhiram/anaconda3/lib/python3.7/site-packages/django/conf/__init__.py", line 172, in __init__
    raise ValueError("Incorrect timezone setting: %s" % self.TIME_ZONE)
ValueError: Incorrect timezone setting: Asia/Kolkat
Performing system checks...

System check identified no issues (0 silenced).
February 12, 2022 - 18:43:05
Django version 3.0.7, using settings 'backend.settings'
Starting development server at http://0.0.0.0:8000/
Quit the server with CONTROL-C.
Performing system checks...

System check identified no issues (0 silenced).
February 12, 2022 - 18:43:57
Django version 3.0.7, using settings 'backend.settings'
Starting development server at http://0.0.0.0:8000/
Quit the server with CONTROL-C.
Performing system checks...

System check identified no issues (0 silenced).
February 12, 2022 - 18:44:42
Django version 3.0.7, using settings 'backend.settings'
Starting development server at http://0.0.0.0:8000/
Quit the server with CONTROL-C.
Performing system checks...

System check identified no issues (0 silenced).
February 12, 2022 - 18:45:07
Django version 3.0.7, using settings 'backend.settings'
Starting development server at http://0.0.0.0:8000/
Quit the server with CONTROL-C.
Performing system checks...

System check identified no issues (0 silenced).
February 12, 2022 - 18:45:25
Django version 3.0.7, using settings 'backend.settings'
Starting development server at http://0.0.0.0:8000/
Quit the server with CONTROL-C.
Performing system checks...

System check identified no issues (0 silenced).
February 12, 2022 - 18:45:40
Django version 3.0.7, using settings 'backend.settings'
Starting development server at http://0.0.0.0:8000/
Quit the server with CONTROL-C.
Performing system checks...

System check identified no issues (0 silenced).
February 12, 2022 - 18:45:50
Django version 3.0.7, using settings 'backend.settings'
Starting development server at http://0.0.0.0:8000/
Quit the server with CONTROL-C.
Performing system checks...

System check identified no issues (0 silenced).
February 12, 2022 - 19:15:09
Django version 3.0.7, using settings 'backend.settings'
Starting development server at http://0.0.0.0:8000/
Quit the server with CONTROL-C.
Performing system checks...

System check identified no issues (0 silenced).
February 12, 2022 - 19:36:23
Django version 3.0.7, using settings 'backend.settings'
Starting development server at http://0.0.0.0:8000/
Quit the server with CONTROL-C.
Traceback (most recent call last):
  File "manage.py", line 22, in <module>
    main()
  File "manage.py", line 18, in main
    execute_from_command_line(sys.argv)
  File "/home/abhiram/anaconda3/lib/python3.7/site-packages/django/core/management/__init__.py", line 401, in execute_from_command_line
    utility.execute()
  File "/home/abhiram/anaconda3/lib/python3.7/site-packages/django/core/management/__init__.py", line 395, in execute
    self.fetch_command(subcommand).run_from_argv(self.argv)
  File "/home/abhiram/anaconda3/lib/python3.7/site-packages/django/core/management/base.py", line 328, in run_from_argv
    self.execute(*args, **cmd_options)
  File "/home/abhiram/anaconda3/lib/python3.7/site-packages/django/core/management/commands/runserver.py", line 60, in execute
    super().execute(*args, **options)
  File "/home/abhiram/anaconda3/lib/python3.7/site-packages/django/core/management/base.py", line 369, in execute
    output = self.handle(*args, **options)
  File "/home/abhiram/anaconda3/lib/python3.7/site-packages/django/core/management/commands/runserver.py", line 95, in handle
    self.run(**options)
  File "/home/abhiram/anaconda3/lib/python3.7/site-packages/django/core/management/commands/runserver.py", line 102, in run
    autoreload.run_with_reloader(self.inner_run, **options)
  File "/home/abhiram/anaconda3/lib/python3.7/site-packages/django/utils/autoreload.py", line 599, in run_with_reloader
    start_django(reloader, main_func, *args, **kwargs)
  File "/home/abhiram/anaconda3/lib/python3.7/site-packages/django/utils/autoreload.py", line 584, in start_django
    reloader.run(django_main_thread)
  File "/home/abhiram/anaconda3/lib/python3.7/site-packages/django/utils/autoreload.py", line 299, in run
    self.run_loop()
  File "/home/abhiram/anaconda3/lib/python3.7/site-packages/django/utils/autoreload.py", line 305, in run_loop
    next(ticker)
  File "/home/abhiram/anaconda3/lib/python3.7/site-packages/django/utils/autoreload.py", line 345, in tick
    for filepath, mtime in self.snapshot_files():
  File "/home/abhiram/anaconda3/lib/python3.7/site-packages/django/utils/autoreload.py", line 361, in snapshot_files
    for file in self.watched_files():
  File "/home/abhiram/anaconda3/lib/python3.7/site-packages/django/utils/autoreload.py", line 265, in watched_files
    yield from directory.glob(pattern)
  File "/home/abhiram/anaconda3/lib/python3.7/pathlib.py", line 1093, in glob
    for p in selector.select_from(self):
  File "/home/abhiram/anaconda3/lib/python3.7/pathlib.py", line 552, in _select_from
    for starting_point in self._iterate_directories(parent_path, is_dir, scandir):
  File "/home/abhiram/anaconda3/lib/python3.7/pathlib.py", line 542, in _iterate_directories
    for p in self._iterate_directories(path, is_dir, scandir):
  File "/home/abhiram/anaconda3/lib/python3.7/pathlib.py", line 542, in _iterate_directories
    for p in self._iterate_directories(path, is_dir, scandir):
  File "/home/abhiram/anaconda3/lib/python3.7/pathlib.py", line 532, in _iterate_directories
    entries = list(scandir(parent_path))
FileNotFoundError: [Errno 2] No such file or directory: '/home/abhiram/anaconda3/lib/python3.7/site-packages/django/contrib/admin/locale/udm/LC_MESSAGES'
Performing system checks...

System check identified no issues (0 silenced).

You have 1 unapplied migration(s). Your project may not work properly until you apply the migrations for app(s): auth.
Run 'python manage.py migrate' to apply them.
February 12, 2022 - 19:40:27
Django version 3.1.7, using settings 'backend.settings'
Starting development server at http://0.0.0.0:8000/
Quit the server with CONTROL-C.
Performing system checks...

System check identified no issues (0 silenced).

You have 1 unapplied migration(s). Your project may not work properly until you apply the migrations for app(s): auth.
Run 'python manage.py migrate' to apply them.
February 12, 2022 - 19:40:53
Django version 3.1.7, using settings 'backend.settings'
Starting development server at http://0.0.0.0:8000/
Quit the server with CONTROL-C.
Performing system checks...

System check identified no issues (0 silenced).

You have 1 unapplied migration(s). Your project may not work properly until you apply the migrations for app(s): auth.
Run 'python manage.py migrate' to apply them.
February 12, 2022 - 19:41:20
Django version 3.1.7, using settings 'backend.settings'
Starting development server at http://0.0.0.0:8000/
Quit the server with CONTROL-C.
Performing system checks...

System check identified no issues (0 silenced).

You have 1 unapplied migration(s). Your project may not work properly until you apply the migrations for app(s): auth.
Run 'python manage.py migrate' to apply them.
February 12, 2022 - 19:41:26
Django version 3.1.7, using settings 'backend.settings'
Starting development server at http://0.0.0.0:8000/
Quit the server with CONTROL-C.
Exception in thread django-main-thread:
Traceback (most recent call last):
  File "/home/abhiram/anaconda3/lib/python3.7/threading.py", line 917, in _bootstrap_inner
    self.run()
  File "/home/abhiram/anaconda3/lib/python3.7/threading.py", line 865, in run
    self._target(*self._args, **self._kwargs)
  File "/home/abhiram/anaconda3/lib/python3.7/site-packages/django/utils/autoreload.py", line 53, in wrapper
    fn(*args, **kwargs)
  File "/home/abhiram/anaconda3/lib/python3.7/site-packages/django/core/management/commands/runserver.py", line 110, in inner_run
    autoreload.raise_last_exception()
  File "/home/abhiram/anaconda3/lib/python3.7/site-packages/django/utils/autoreload.py", line 76, in raise_last_exception
    raise _exception[1]
  File "/home/abhiram/anaconda3/lib/python3.7/site-packages/django/core/management/__init__.py", line 357, in execute
    autoreload.check_errors(django.setup)()
  File "/home/abhiram/anaconda3/lib/python3.7/site-packages/django/utils/autoreload.py", line 53, in wrapper
    fn(*args, **kwargs)
  File "/home/abhiram/anaconda3/lib/python3.7/site-packages/django/__init__.py", line 24, in setup
    apps.populate(settings.INSTALLED_APPS)
  File "/home/abhiram/anaconda3/lib/python3.7/site-packages/django/apps/registry.py", line 91, in populate
    app_config = AppConfig.create(entry)
  File "/home/abhiram/anaconda3/lib/python3.7/site-packages/django/apps/config.py", line 90, in create
    module = import_module(entry)
  File "/home/abhiram/anaconda3/lib/python3.7/importlib/__init__.py", line 127, in import_module
    return _bootstrap._gcd_import(name[level:], package, level)
  File "<frozen importlib._bootstrap>", line 1006, in _gcd_import
  File "<frozen importlib._bootstrap>", line 983, in _find_and_load
  File "<frozen importlib._bootstrap>", line 965, in _find_and_load_unlocked
ModuleNotFoundError: No module named 'corsheaders'

Exception in thread django-main-thread:
Traceback (most recent call last):
  File "/home/abhiram/anaconda3/lib/python3.7/threading.py", line 917, in _bootstrap_inner
    self.run()
  File "/home/abhiram/anaconda3/lib/python3.7/threading.py", line 865, in run
    self._target(*self._args, **self._kwargs)
  File "/home/abhiram/anaconda3/lib/python3.7/site-packages/django/utils/autoreload.py", line 53, in wrapper
    fn(*args, **kwargs)
  File "/home/abhiram/anaconda3/lib/python3.7/site-packages/django/core/management/commands/runserver.py", line 110, in inner_run
    autoreload.raise_last_exception()
  File "/home/abhiram/anaconda3/lib/python3.7/site-packages/django/utils/autoreload.py", line 76, in raise_last_exception
    raise _exception[1]
  File "/home/abhiram/anaconda3/lib/python3.7/site-packages/django/core/management/__init__.py", line 357, in execute
    autoreload.check_errors(django.setup)()
  File "/home/abhiram/anaconda3/lib/python3.7/site-packages/django/utils/autoreload.py", line 53, in wrapper
    fn(*args, **kwargs)
  File "/home/abhiram/anaconda3/lib/python3.7/site-packages/django/__init__.py", line 24, in setup
    apps.populate(settings.INSTALLED_APPS)
  File "/home/abhiram/anaconda3/lib/python3.7/site-packages/django/apps/registry.py", line 91, in populate
    app_config = AppConfig.create(entry)
  File "/home/abhiram/anaconda3/lib/python3.7/site-packages/django/apps/config.py", line 90, in create
    module = import_module(entry)
  File "/home/abhiram/anaconda3/lib/python3.7/importlib/__init__.py", line 127, in import_module
    return _bootstrap._gcd_import(name[level:], package, level)
  File "<frozen importlib._bootstrap>", line 1006, in _gcd_import
  File "<frozen importlib._bootstrap>", line 983, in _find_and_load
  File "<frozen importlib._bootstrap>", line 965, in _find_and_load_unlocked
ModuleNotFoundError: No module named 'corsheaders'

Exception in thread django-main-thread:
Traceback (most recent call last):
  File "/home/abhiram/anaconda3/lib/python3.7/threading.py", line 917, in _bootstrap_inner
    self.run()
  File "/home/abhiram/anaconda3/lib/python3.7/threading.py", line 865, in run
    self._target(*self._args, **self._kwargs)
  File "/home/abhiram/anaconda3/lib/python3.7/site-packages/django/utils/autoreload.py", line 53, in wrapper
    fn(*args, **kwargs)
  File "/home/abhiram/anaconda3/lib/python3.7/site-packages/django/core/management/commands/runserver.py", line 110, in inner_run
    autoreload.raise_last_exception()
  File "/home/abhiram/anaconda3/lib/python3.7/site-packages/django/utils/autoreload.py", line 76, in raise_last_exception
    raise _exception[1]
  File "/home/abhiram/anaconda3/lib/python3.7/site-packages/django/core/management/__init__.py", line 357, in execute
    autoreload.check_errors(django.setup)()
  File "/home/abhiram/anaconda3/lib/python3.7/site-packages/django/utils/autoreload.py", line 53, in wrapper
    fn(*args, **kwargs)
  File "/home/abhiram/anaconda3/lib/python3.7/site-packages/django/__init__.py", line 24, in setup
    apps.populate(settings.INSTALLED_APPS)
  File "/home/abhiram/anaconda3/lib/python3.7/site-packages/django/apps/registry.py", line 91, in populate
    app_config = AppConfig.create(entry)
  File "/home/abhiram/anaconda3/lib/python3.7/site-packages/django/apps/config.py", line 90, in create
    module = import_module(entry)
  File "/home/abhiram/anaconda3/lib/python3.7/importlib/__init__.py", line 127, in import_module
    return _bootstrap._gcd_import(name[level:], package, level)
  File "<frozen importlib._bootstrap>", line 1006, in _gcd_import
  File "<frozen importlib._bootstrap>", line 983, in _find_and_load
  File "<frozen importlib._bootstrap>", line 965, in _find_and_load_unlocked
ModuleNotFoundError: No module named 'corsheaders'

Exception in thread django-main-thread:
Traceback (most recent call last):
  File "/home/abhiram/anaconda3/lib/python3.7/threading.py", line 917, in _bootstrap_inner
    self.run()
  File "/home/abhiram/anaconda3/lib/python3.7/threading.py", line 865, in run
    self._target(*self._args, **self._kwargs)
  File "/home/abhiram/anaconda3/lib/python3.7/site-packages/django/utils/autoreload.py", line 53, in wrapper
    fn(*args, **kwargs)
  File "/home/abhiram/anaconda3/lib/python3.7/site-packages/django/core/management/commands/runserver.py", line 110, in inner_run
    autoreload.raise_last_exception()
  File "/home/abhiram/anaconda3/lib/python3.7/site-packages/django/utils/autoreload.py", line 76, in raise_last_exception
    raise _exception[1]
  File "/home/abhiram/anaconda3/lib/python3.7/site-packages/django/core/management/__init__.py", line 357, in execute
    autoreload.check_errors(django.setup)()
  File "/home/abhiram/anaconda3/lib/python3.7/site-packages/django/utils/autoreload.py", line 53, in wrapper
    fn(*args, **kwargs)
  File "/home/abhiram/anaconda3/lib/python3.7/site-packages/django/__init__.py", line 24, in setup
    apps.populate(settings.INSTALLED_APPS)
  File "/home/abhiram/anaconda3/lib/python3.7/site-packages/django/apps/registry.py", line 91, in populate
    app_config = AppConfig.create(entry)
  File "/home/abhiram/anaconda3/lib/python3.7/site-packages/django/apps/config.py", line 90, in create
    module = import_module(entry)
  File "/home/abhiram/anaconda3/lib/python3.7/importlib/__init__.py", line 127, in import_module
    return _bootstrap._gcd_import(name[level:], package, level)
  File "<frozen importlib._bootstrap>", line 1006, in _gcd_import
  File "<frozen importlib._bootstrap>", line 983, in _find_and_load
  File "<frozen importlib._bootstrap>", line 965, in _find_and_load_unlocked
ModuleNotFoundError: No module named 'corsheaders'

Exception in thread django-main-thread:
Traceback (most recent call last):
  File "/home/abhiram/anaconda3/lib/python3.7/threading.py", line 917, in _bootstrap_inner
    self.run()
  File "/home/abhiram/anaconda3/lib/python3.7/threading.py", line 865, in run
    self._target(*self._args, **self._kwargs)
  File "/home/abhiram/anaconda3/lib/python3.7/site-packages/django/utils/autoreload.py", line 53, in wrapper
    fn(*args, **kwargs)
  File "/home/abhiram/anaconda3/lib/python3.7/site-packages/django/core/management/commands/runserver.py", line 110, in inner_run
    autoreload.raise_last_exception()
  File "/home/abhiram/anaconda3/lib/python3.7/site-packages/django/utils/autoreload.py", line 76, in raise_last_exception
    raise _exception[1]
  File "/home/abhiram/anaconda3/lib/python3.7/site-packages/django/core/management/__init__.py", line 357, in execute
    autoreload.check_errors(django.setup)()
  File "/home/abhiram/anaconda3/lib/python3.7/site-packages/django/utils/autoreload.py", line 53, in wrapper
    fn(*args, **kwargs)
  File "/home/abhiram/anaconda3/lib/python3.7/site-packages/django/__init__.py", line 24, in setup
    apps.populate(settings.INSTALLED_APPS)
  File "/home/abhiram/anaconda3/lib/python3.7/site-packages/django/apps/registry.py", line 91, in populate
    app_config = AppConfig.create(entry)
  File "/home/abhiram/anaconda3/lib/python3.7/site-packages/django/apps/config.py", line 90, in create
    module = import_module(entry)
  File "/home/abhiram/anaconda3/lib/python3.7/importlib/__init__.py", line 127, in import_module
    return _bootstrap._gcd_import(name[level:], package, level)
  File "<frozen importlib._bootstrap>", line 1006, in _gcd_import
  File "<frozen importlib._bootstrap>", line 983, in _find_and_load
  File "<frozen importlib._bootstrap>", line 965, in _find_and_load_unlocked
ModuleNotFoundError: No module named 'corsheaders'

Exception in thread django-main-thread:
Traceback (most recent call last):
  File "/home/abhiram/anaconda3/lib/python3.7/threading.py", line 917, in _bootstrap_inner
    self.run()
  File "/home/abhiram/anaconda3/lib/python3.7/threading.py", line 865, in run
    self._target(*self._args, **self._kwargs)
  File "/home/abhiram/anaconda3/lib/python3.7/site-packages/django/utils/autoreload.py", line 53, in wrapper
    fn(*args, **kwargs)
  File "/home/abhiram/anaconda3/lib/python3.7/site-packages/django/core/management/commands/runserver.py", line 110, in inner_run
    autoreload.raise_last_exception()
  File "/home/abhiram/anaconda3/lib/python3.7/site-packages/django/utils/autoreload.py", line 76, in raise_last_exception
    raise _exception[1]
  File "/home/abhiram/anaconda3/lib/python3.7/site-packages/django/core/management/__init__.py", line 357, in execute
    autoreload.check_errors(django.setup)()
  File "/home/abhiram/anaconda3/lib/python3.7/site-packages/django/utils/autoreload.py", line 53, in wrapper
    fn(*args, **kwargs)
  File "/home/abhiram/anaconda3/lib/python3.7/site-packages/django/__init__.py", line 24, in setup
    apps.populate(settings.INSTALLED_APPS)
  File "/home/abhiram/anaconda3/lib/python3.7/site-packages/django/apps/registry.py", line 91, in populate
    app_config = AppConfig.create(entry)
  File "/home/abhiram/anaconda3/lib/python3.7/site-packages/django/apps/config.py", line 90, in create
    module = import_module(entry)
  File "/home/abhiram/anaconda3/lib/python3.7/importlib/__init__.py", line 127, in import_module
    return _bootstrap._gcd_import(name[level:], package, level)
  File "<frozen importlib._bootstrap>", line 1006, in _gcd_import
  File "<frozen importlib._bootstrap>", line 983, in _find_and_load
  File "<frozen importlib._bootstrap>", line 965, in _find_and_load_unlocked
ModuleNotFoundError: No module named 'corsheaders'

